<?xml version = "1.0" encoding = "utf-8" ?>
<!DOCTYPE html PUBLIC "-//W3C//DTD XHTML 1.0 Strict//EN" "http://www.w3.org/TR/xhtml1/DTD/xhtml1-strict.dtd">
<html xmlns = "http://www.w3.org/1999/xhtml" xml:lang = "en" lang = "en">
<head>
    <title>pDynamo Python Method assertRaises</title>
    <link href = "documentationPages.css" rel = "stylesheet" type = "text/css" />
</head>

<body>

<!-- =========================================================================================================================== -->
<!-- Header. -->
<!-- =========================================================================================================================== -->
<div class = "header">

    <!-- Title -->
    <div class = "headertitle">
        <h1 class = "header">pDynamo Library Reference</h1>
    </div>

    <!-- Searching -->
    <div class = "searching">
        <form action = "http://google.com/search" method = "get">
            <div>
                <input                  name = "domains"    type = "hidden" value = "www.pdynamo.org" />
                <input                  name = "sitesearch" type = "hidden" value = "www.pdynamo.org" />
                <input                  name = "sourceid"   type = "hidden" value = "google-search"   />
                <input class = "text"   name = "q"          type = "text"                             />
                <input class = "submit" name = "submit"     type = "submit" value = "Search Site"     />
            </div>
        </form>
    </div>

</div>

<!-- Orange line separator. -->
<div class = "orangeline">&nbsp;</div>

<h1 class = "title"><a id = "top">Python Method assertRaises</a></h1>

<p>Owner: <a href = "class326.html">Class TestCase</a></p>

<div class = "description">
    <p>
    Fail unless an exception of class excClass is raised by
    callableObj when invoked with arguments args and keyword arguments
    kwargs. If a different type of exception is raised, it will not be
    caught, and the test case will be deemed to have suffered an
    error, exactly as for an unexpected exception.
    </p>
    <p>
    If called with callableObj omitted or None, will return a context
    object used like this::
    </p>
    <p>
    with self.assertRaises(SomeException):          do_something()
    </p>
    <p>
    The context manager keeps a reference to the exception as the
    'exception' attribute. This allows you to inspect the exception
    after the assertion::
    </p>
    <p>
    with self.assertRaises(SomeException) as cm:
    do_something()     the_exception = cm.exception
    self.assertEqual(the_exception.error_code, 3)
    </p>
</div>

<!-- =========================================================================================================================== -->
<!-- Footer. -->
<!-- =========================================================================================================================== -->

<!-- Orange line separator. -->
<div class = "orangeline">&nbsp;</div>

<div class = "footer">
    <div class = "validation">
        <img src = "valid-xhtml10.gif" alt = "Valid XHTML 1.0 Strict" height = "31" width = "88" />
    </div>
    Generation time (GMT): Fri Nov 14 13:34:36 2014<br />
    pDynamo version: 1.9.0
</div>

</body>
</html>
